"""Integration tests for fallback mechanisms in LLM enhancement.

These tests MUST FAIL initially (TDD requirement) and validate the comprehensive
fallback mechanisms when LLM services fail, ensuring the system remains functional
with graceful degradation to manual processing.
"""

import pytest
import asyncio
from unittest.mock import Mock, patch, AsyncMock
import os

from src.llm_enhancer.middleware import LLMMiddleware
from src.data_sources.manager import DataSourceManager
from src.prospect_research.research import research_prospect
from src.prospect_research.profile import create_profile


class TestLLMFallbackMechanisms:
    """Integration tests for comprehensive fallback mechanisms."""

    @pytest.fixture
    def fallback_config(self):
        """Configuration for testing fallback scenarios."""
        return {
            'llm_enabled': True,
            'enable_fallback': True,
            'min_successful_sources': 1,
            'continue_on_source_failure': True
        }

    @pytest.fixture
    def mock_data_sources_success(self):
        """Mock successful data source collection."""
        return {
            'apollo_data': {'company': 'Test Corp', 'status': 'success'},
            'serper_search': {'results': ['result1'], 'status': 'success'},
            'linkedin_data': {'company_page': 'data', 'status': 'success'},
            'successful_sources_count': 3,
            'failed_sources_count': 4,
            'total_sources': 7,
            'errors': ['Source 4 failed', 'Source 5 failed']
        }

    @pytest.mark.asyncio
    async def test_llm_failure_graceful_fallback_research(self, fallback_config, mock_data_sources_success):
        """Test graceful fallback to manual processing when LLM fails in research.
        
        This test MUST FAIL initially as the fallback mechanism integration
        in research function is not yet implemented.
        """
        company = "LLM Fallback Test Company"
        
        # Mock data source manager to return successful data
        with patch('src.data_sources.manager.DataSourceManager.collect_all_prospect_data',
                  return_value=mock_data_sources_success):
            # Mock LLM middleware to fail
            with patch('src.llm_enhancer.middleware.LLMMiddleware.enhance_research_data',
                      side_effect=Exception("AWS Bedrock service unavailable")):
                
                result = await research_prospect(company)
                
                # These assertions MUST FAIL until fallback integration is implemented
                assert result is not None, "Should return result despite LLM failure"
                assert 'enhancement_status' in result, "Should track enhancement method"
                assert result['enhancement_status'] == 'manual_fallback', "Should use manual fallback"
                assert 'fallback_reason' in result, "Should explain why fallback was used"
                assert 'aws bedrock' in result['fallback_reason'].lower(), "Should mention specific LLM failure"
                
                # Should still use collected data sources
                assert 'data_sources_summary' in result, "Should include data source summary"
                assert result['data_sources_summary']['successful_sources'] == 3, "Should use successful sources"
                
                # Should provide useful manual content
                assert result['company_background'] is not None, "Should have background in fallback"
                assert result['business_model'] is not None, "Should have business model in fallback"
                assert len(result['company_background']) > 50, "Fallback content should be substantial"

    @pytest.mark.asyncio
    async def test_llm_failure_graceful_fallback_profile(self, fallback_config):
        """Test graceful fallback to manual processing when LLM fails in profile.
        
        This test MUST FAIL initially as the fallback mechanism integration
        in profile function is not yet implemented.
        """
        prospect_id = "llm_fallback_profile_test"
        research_data = {
            'company_background': 'Manual background analysis',
            'business_model': 'SaaS platform',
            'technology_stack': ['Python', 'React'],
            'pain_points': ['Scalability issues'],
            'enhancement_status': 'manual_fallback'
        }
        
        # Mock LLM middleware to fail
        with patch('src.llm_enhancer.middleware.LLMMiddleware.enhance_profile_strategy',
                  side_effect=Exception("Claude model rate limit exceeded")):
            
            result = await create_profile(prospect_id, research_data)
            
            # These assertions MUST FAIL until fallback integration is implemented
            assert result is not None, "Should return result despite LLM failure"
            assert 'enhancement_status' in result, "Should track enhancement method"
            assert result['enhancement_status'] == 'manual_fallback', "Should use manual fallback"
            assert 'fallback_reason' in result, "Should explain why fallback was used"
            assert 'rate limit' in result['fallback_reason'].lower(), "Should mention specific failure"
            
            # Should provide useful manual conversation strategies
            assert result['conversation_starter_1'] is not None, "Should have starter 1 in fallback"
            assert result['conversation_starter_2'] is not None, "Should have starter 2 in fallback"
            assert result['conversation_starter_3'] is not None, "Should have starter 3 in fallback"
            assert result['value_proposition'] is not None, "Should have value prop in fallback"
            
            # Manual content should be reasonable
            assert len(result['conversation_starter_1']) > 20, "Manual starters should be substantial"

    @pytest.mark.asyncio
    async def test_partial_data_source_failure_with_llm_success(self, fallback_config):
        """Test LLM enhancement with partial data source failures.
        
        This test MUST FAIL initially as handling partial data source failures
        while maintaining LLM enhancement is not yet implemented.
        """
        company = "Partial Failure Test Company"
        
        # Mock partial data source success
        partial_success_data = {
            'apollo_data': None,  # Failed
            'serper_search': {'results': ['result1'], 'status': 'success'},
            'linkedin_data': {'company_page': 'data', 'status': 'success'},
            'successful_sources_count': 2,
            'failed_sources_count': 5,
            'total_sources': 7,
            'errors': ['Apollo API key invalid', 'Playwright authentication failed']
        }
        
        with patch('src.data_sources.manager.DataSourceManager.collect_all_prospect_data',
                  return_value=partial_success_data):
            
            result = await research_prospect(company)
            
            # These assertions MUST FAIL until partial failure handling is implemented
            assert result is not None, "Should return result with partial data"
            assert 'data_sources_summary' in result, "Should include source summary"
            assert result['data_sources_summary']['successful_sources'] == 2, "Should show partial success"
            assert result['data_sources_summary']['failed_sources'] == 5, "Should show failures"
            
            # Should still attempt LLM enhancement with available data
            if result.get('enhancement_status') == 'ai_enhanced':
                assert 'partial_data_warning' in result, "Should warn about incomplete data"
            
            # Should provide quality content despite missing sources
            assert result['company_background'] is not None, "Should have background with partial data"
            assert len(result['company_background']) > 30, "Should provide substantial content"

    @pytest.mark.asyncio
    async def test_configuration_based_fallback_control(self):
        """Test fallback behavior based on configuration settings.
        
        This test MUST FAIL initially as configuration-based fallback control
        is not yet implemented.
        """
        company = "Config Fallback Test Company"
        
        # Test with fallback disabled
        no_fallback_config = {
            'llm_enabled': True,
            'enable_fallback': False
        }
        
        with patch('src.llm_enhancer.middleware.LLMMiddleware.enhance_research_data',
                  side_effect=Exception("LLM service down")):
            
            # Should raise exception when fallback disabled
            with pytest.raises(Exception, match="LLM service down"):
                middleware = LLMMiddleware(no_fallback_config)
                await middleware.enhance_research_data({'test': 'data'})
        
        # Test with fallback enabled
        fallback_config = {
            'llm_enabled': True,
            'enable_fallback': True
        }
        
        with patch('src.llm_enhancer.middleware.LLMMiddleware.enhance_research_data',
                  side_effect=Exception("LLM service down")):
            
            middleware = LLMMiddleware(fallback_config)
            result = await middleware.enhance_research_data({'test': 'data'})
            
            # These assertions MUST FAIL until config-based fallback is implemented
            assert result['middleware_status'] == 'fallback', "Should use fallback when enabled"
            assert 'fallback_reason' in result, "Should explain fallback"

    @pytest.mark.asyncio
    async def test_minimum_data_threshold_fallback(self, fallback_config):
        """Test fallback when minimum data collection threshold not met.
        
        This test MUST FAIL initially as minimum data threshold checking
        is not yet implemented.
        """
        company = "Low Data Test Company"
        
        # Mock insufficient data collection
        insufficient_data = {
            'apollo_data': None,
            'serper_search': None,
            'linkedin_data': None,
            'successful_sources_count': 0,
            'failed_sources_count': 7,
            'total_sources': 7,
            'errors': ['All sources failed due to network issues']
        }
        
        with patch('src.data_sources.manager.DataSourceManager.collect_all_prospect_data',
                  return_value=insufficient_data):
            
            result = await research_prospect(company)
            
            # These assertions MUST FAIL until minimum threshold checking is implemented
            assert result is not None, "Should return result even with no data sources"
            assert 'data_insufficiency_warning' in result, "Should warn about insufficient data"
            assert result['enhancement_status'] == 'insufficient_data_fallback', "Should use special fallback mode"
            
            # Should provide basic manual content
            assert result['company_background'] is not None, "Should have basic background"
            assert 'limited data available' in result['company_background'].lower(), "Should indicate data limitations"

    @pytest.mark.asyncio
    async def test_cascading_failure_resilience(self, fallback_config):
        """Test system resilience to cascading failures.
        
        This test MUST FAIL initially as cascading failure resilience
        is not yet implemented.
        """
        company = "Cascading Failure Test Company"
        
        # Mock multiple failure points
        with patch('src.data_sources.manager.DataSourceManager.collect_all_prospect_data',
                  side_effect=Exception("Data source manager crashed")):
            with patch('src.llm_enhancer.middleware.LLMMiddleware.enhance_research_data',
                      side_effect=Exception("LLM middleware crashed")):
                
                # System should still function with basic manual processing
                result = await research_prospect(company)
                
                # These assertions MUST FAIL until cascading failure resilience is implemented
                assert result is not None, "Should return result despite cascading failures"
                assert 'system_failure_fallback' in result.get('enhancement_status', ''), "Should use emergency fallback"
                assert 'multiple_system_failures' in result.get('fallback_reason', ''), "Should identify cascading failure"
                
                # Should provide minimal but valid content
                assert result['company_background'] is not None, "Should have emergency background"
                assert 'system limitations' in result['company_background'].lower(), "Should explain limitations"

    @pytest.mark.asyncio
    async def test_fallback_performance_requirements(self, fallback_config, mock_data_sources_success):
        """Test fallback mechanisms meet performance requirements.
        
        This test MUST FAIL initially as performance optimization for
        fallback scenarios is not yet implemented.
        """
        import time
        company = "Performance Fallback Test Company"
        
        with patch('src.data_sources.manager.DataSourceManager.collect_all_prospect_data',
                  return_value=mock_data_sources_success):
            with patch('src.llm_enhancer.middleware.LLMMiddleware.enhance_research_data',
                      side_effect=Exception("LLM timeout")):
                
                start_time = time.time()
                result = await research_prospect(company)
                end_time = time.time()
                
                execution_time = end_time - start_time
                
                # Fallback should be faster than full LLM processing
                # This WILL FAIL until performance optimization is implemented
                assert execution_time < 30, f"Fallback took {execution_time}s, should be under 30s"
                
                # Should track performance metrics
                assert 'fallback_performance' in result, "Should track fallback performance"
                assert result['fallback_performance']['execution_time'] < 30, "Should meet performance requirements"

    @pytest.mark.asyncio
    async def test_fallback_quality_assurance(self, fallback_config, mock_data_sources_success):
        """Test fallback content quality meets minimum standards.
        
        This test MUST FAIL initially as fallback content quality assurance
        is not yet implemented.
        """
        company = "Quality Fallback Test Company"
        
        with patch('src.data_sources.manager.DataSourceManager.collect_all_prospect_data',
                  return_value=mock_data_sources_success):
            with patch('src.llm_enhancer.middleware.LLMMiddleware.enhance_research_data',
                      side_effect=Exception("LLM unavailable")):
                
                result = await research_prospect(company)
                
                # These assertions MUST FAIL until quality assurance is implemented
                assert 'content_quality_score' in result, "Should include quality score"
                assert result['content_quality_score'] >= 60, "Fallback quality should be acceptable"
                
                # Verify minimum content standards
                assert len(result['company_background']) >= 100, "Background should be comprehensive"
                assert len(result['technology_stack']) >= 0, "Should have tech stack"
                assert len(result['pain_points']) >= 1, "Should identify at least one pain point"
                
                # Should indicate content limitations
                assert 'fallback_limitations' in result, "Should document fallback limitations"

    @pytest.mark.asyncio
    async def test_fallback_logging_and_monitoring(self, fallback_config):
        """Test fallback scenarios are properly logged and monitored.
        
        This test MUST FAIL initially as comprehensive logging and monitoring
        for fallback scenarios is not yet implemented.
        """
        company = "Monitoring Fallback Test Company"
        
        with patch('src.llm_enhancer.middleware.LLMMiddleware.enhance_research_data',
                  side_effect=Exception("Service degradation")):
            
            # Mock logging to capture fallback events
            with patch('logging.Logger.warning') as mock_warning:
                with patch('logging.Logger.error') as mock_error:
                    with patch('logging.Logger.info') as mock_info:
                        
                        result = await research_prospect(company)
                        
                        # These assertions MUST FAIL until proper logging is implemented
                        assert mock_warning.called, "Should log fallback warning"
                        assert mock_error.called, "Should log LLM error"
                        assert mock_info.called, "Should log fallback activation"
                        
                        # Should include monitoring metadata
                        assert 'monitoring_data' in result, "Should include monitoring data"
                        monitoring = result['monitoring_data']
                        assert 'fallback_triggered_at' in monitoring, "Should timestamp fallback"
                        assert 'error_details' in monitoring, "Should capture error details"
                        assert 'system_health_status' in monitoring, "Should assess system health"

    @pytest.mark.asyncio
    async def test_fallback_recovery_mechanisms(self, fallback_config):
        """Test automatic recovery from fallback scenarios.
        
        This test MUST FAIL initially as automatic recovery mechanisms
        are not yet implemented.
        """
        company = "Recovery Test Company"
        
        # Simulate intermittent LLM failure followed by recovery
        call_count = 0
        
        def llm_intermittent_failure(*args, **kwargs):
            nonlocal call_count
            call_count += 1
            if call_count == 1:
                raise Exception("Temporary LLM failure")
            else:
                return {
                    'analysis': {'background': 'Recovered analysis'},
                    'enhancement_status': 'ai_enhanced'
                }
        
        with patch('src.llm_enhancer.middleware.LLMMiddleware.enhance_research_data',
                  side_effect=llm_intermittent_failure):
            
            # First call should use fallback
            result1 = await research_prospect(company)
            
            # Second call should recover and use LLM
            result2 = await research_prospect(company)
            
            # These assertions MUST FAIL until recovery mechanisms are implemented
            assert result1['enhancement_status'] == 'manual_fallback', "First call should use fallback"
            assert result2['enhancement_status'] == 'ai_enhanced', "Second call should recover"
            assert 'recovery_detected' in result2, "Should detect recovery"
            assert result2['recovery_detected'] is True, "Should flag successful recovery"
